{"metadata":{"kernelspec":{"language":"python","display_name":"Python 3","name":"python3"},"language_info":{"name":"python","version":"3.10.14","mimetype":"text/x-python","codemirror_mode":{"name":"ipython","version":3},"pygments_lexer":"ipython3","nbconvert_exporter":"python","file_extension":".py"},"kaggle":{"accelerator":"none","dataSources":[],"dockerImageVersionId":30786,"isInternetEnabled":false,"language":"python","sourceType":"notebook","isGpuEnabled":false}},"nbformat_minor":4,"nbformat":4,"cells":[{"cell_type":"markdown","source":"Q1. What is an Exception in python? Write the difference between Exceptions and Syntax errors.","metadata":{}},{"cell_type":"markdown","source":"An exception in Python is an error that occurs during program execution, like division by zero or accessing a non-existent file, and can be handled using try/except blocks.\n\nA syntax error occurs when there is an issue with the code structure (e.g., missing parentheses or incorrect indentation), and it prevents the program from running until fixed.","metadata":{}},{"cell_type":"code","source":"","metadata":{"trusted":true},"outputs":[],"execution_count":null},{"cell_type":"markdown","source":"Q2. What happens when an exception is not handled? Explain with an example.","metadata":{}},{"cell_type":"markdown","source":"When an exception is not handled in Python, it causes the program to terminate abruptly. The Python interpreter prints a traceback, which shows where the exception occurred, and the program stops execution at that point.","metadata":{}},{"cell_type":"code","source":"# Example: Division by zero without handling the exception\nx = 10\ny = 0\n\nresult = x / y\nprint(\"This line will not be executed.\")\n","metadata":{"trusted":true,"execution":{"iopub.status.busy":"2024-11-10T05:08:48.773885Z","iopub.execute_input":"2024-11-10T05:08:48.774406Z","iopub.status.idle":"2024-11-10T05:08:49.202357Z","shell.execute_reply.started":"2024-11-10T05:08:48.774347Z","shell.execute_reply":"2024-11-10T05:08:49.200740Z"}},"outputs":[{"traceback":["\u001b[0;31m---------------------------------------------------------------------------\u001b[0m","\u001b[0;31mZeroDivisionError\u001b[0m                         Traceback (most recent call last)","Cell \u001b[0;32mIn[1], line 6\u001b[0m\n\u001b[1;32m      3\u001b[0m y \u001b[38;5;241m=\u001b[39m \u001b[38;5;241m0\u001b[39m\n\u001b[1;32m      5\u001b[0m \u001b[38;5;66;03m# This will raise a ZeroDivisionError\u001b[39;00m\n\u001b[0;32m----> 6\u001b[0m result \u001b[38;5;241m=\u001b[39m \u001b[43mx\u001b[49m\u001b[43m \u001b[49m\u001b[38;5;241;43m/\u001b[39;49m\u001b[43m \u001b[49m\u001b[43my\u001b[49m\n\u001b[1;32m      7\u001b[0m \u001b[38;5;28mprint\u001b[39m(\u001b[38;5;124m\"\u001b[39m\u001b[38;5;124mThis line will not be executed.\u001b[39m\u001b[38;5;124m\"\u001b[39m)\n","\u001b[0;31mZeroDivisionError\u001b[0m: division by zero"],"ename":"ZeroDivisionError","evalue":"division by zero","output_type":"error"}],"execution_count":1},{"cell_type":"code","source":"","metadata":{"trusted":true},"outputs":[],"execution_count":null},{"cell_type":"markdown","source":"Q3. Which Python statements are used to catch and handle exceptions? Explain with an example.","metadata":{}},{"cell_type":"markdown","source":"In Python, exceptions are caught and handled using the try, except, else, and finally statements.\n\ntry: This block contains code that might raise an exception.\n\nexcept: This block catches and handles the exception that was raised in the try block.\n\nelse: This block executes if no exception was raised in the try block.","metadata":{}},{"cell_type":"code","source":"try:\n    # Code that might raise an exception\n    x = 10\n    y = 0\n    result = x / y  # Division by zero will raise an exception\nexcept ZeroDivisionError as e:\n    # Handling the specific exception\n    print(f\"Error: {e}\")\nelse:\n    # This block runs if no exception occurred\n    print(\"No exceptions occurred, result is:\", result)\n\n","metadata":{"trusted":true,"execution":{"iopub.status.busy":"2024-11-10T05:10:29.875690Z","iopub.execute_input":"2024-11-10T05:10:29.876119Z","iopub.status.idle":"2024-11-10T05:10:29.884007Z","shell.execute_reply.started":"2024-11-10T05:10:29.876079Z","shell.execute_reply":"2024-11-10T05:10:29.882501Z"}},"outputs":[{"name":"stdout","text":"Error: division by zero\n","output_type":"stream"}],"execution_count":2},{"cell_type":"code","source":"","metadata":{"trusted":true},"outputs":[],"execution_count":null},{"cell_type":"markdown","source":"Q4. Explain with an example: try and else , finally and raiseise","metadata":{}},{"cell_type":"markdown","source":"try: Used to write code that might raise an exception.\n\nelse: Runs if no exception occurs in the try block.\n\nfinally: Always runs, regardless of whether an exception occurred, often used for cleanup.\n\nraise: Used to manually raise an exception.","metadata":{}},{"cell_type":"code","source":"def divide_numbers(a, b):\n    try:\n        if b == 0:\n            raise ValueError(\"Cannot divide by zero!\")\n        result = a / b\n    except ValueError as ve:\n        print(f\"Error: {ve}\")\n        return None\n    else:\n        print(\"Result:\", result)\n        return result\n    finally:\n        print(\"Execution complete.\")\n\ndivide_numbers(10, 0)\n","metadata":{"trusted":true,"execution":{"iopub.status.busy":"2024-11-10T05:13:16.071303Z","iopub.execute_input":"2024-11-10T05:13:16.071792Z","iopub.status.idle":"2024-11-10T05:13:16.081040Z","shell.execute_reply.started":"2024-11-10T05:13:16.071748Z","shell.execute_reply":"2024-11-10T05:13:16.079599Z"}},"outputs":[{"name":"stdout","text":"Error: Cannot divide by zero!\nExecution complete.\n","output_type":"stream"}],"execution_count":3},{"cell_type":"code","source":"","metadata":{"trusted":true},"outputs":[],"execution_count":null},{"cell_type":"markdown","source":"Q5. What are Custom Exceptions in python? Why do we need Custom Exceptions? Explain with an example.","metadata":{}},{"cell_type":"markdown","source":"A custom exception is a user-defined error that helps represent specific error conditions in your program. You create one by defining a class that inherits from Pythonâ€™s built-in Exception class.\n\nClarity: Provides more meaningful and specific error messages.\n\nBetter Error Handling: Allows more granular control over error handling in your program.","metadata":{}},{"cell_type":"code","source":"class InsufficientFundsError(Exception):\n    def __init__(self, message=\"Insufficient funds\"):\n        self.message = message\n        super().__init__(self.message)\n\ndef withdraw(amount, balance):\n    if amount > balance:\n        raise InsufficientFundsError(f\"Cannot withdraw {amount}, balance is {balance}\")\n    return balance - amount\n\ntry:\n    balance = 100\n    balance = withdraw(150, balance)\nexcept InsufficientFundsError as e:\n    print(f\"Error: {e}\")\n","metadata":{"trusted":true,"execution":{"iopub.status.busy":"2024-11-10T05:14:39.683039Z","iopub.execute_input":"2024-11-10T05:14:39.683521Z","iopub.status.idle":"2024-11-10T05:14:39.692642Z","shell.execute_reply.started":"2024-11-10T05:14:39.683475Z","shell.execute_reply":"2024-11-10T05:14:39.691181Z"}},"outputs":[{"name":"stdout","text":"Error: Cannot withdraw 150, balance is 100\n","output_type":"stream"}],"execution_count":4},{"cell_type":"code","source":"","metadata":{"trusted":true},"outputs":[],"execution_count":null},{"cell_type":"markdown","source":"Q6. Create a custom exception class. Use this class to handle an exception.","metadata":{}},{"cell_type":"code","source":"class InvalidAgeError(Exception):\n    def __init__(self, message=\"Age must be between 0 and 150\"):\n        self.message = message\n        super().__init__(self.message)\n\ndef check_age(age):\n    if age < 0 or age > 150:\n        raise InvalidAgeError(f\"Invalid age: {age}. Age must be between 0 and 150.\")\n    else:\n        print(f\"Age {age} is valid.\")\n\n\ntry:\n    age = -5  \n    check_age(age)\nexcept InvalidAgeError as e:\n    print(f\"Error: {e}\")\n","metadata":{"trusted":true,"execution":{"iopub.status.busy":"2024-11-10T05:15:42.286517Z","iopub.execute_input":"2024-11-10T05:15:42.287060Z","iopub.status.idle":"2024-11-10T05:15:42.298231Z","shell.execute_reply.started":"2024-11-10T05:15:42.287012Z","shell.execute_reply":"2024-11-10T05:15:42.296518Z"}},"outputs":[{"name":"stdout","text":"Error: Invalid age: -5. Age must be between 0 and 150.\n","output_type":"stream"}],"execution_count":6},{"cell_type":"code","source":"","metadata":{"trusted":true},"outputs":[],"execution_count":null}]}