{"metadata":{"kernelspec":{"language":"python","display_name":"Python 3","name":"python3"},"language_info":{"name":"python","version":"3.10.14","mimetype":"text/x-python","codemirror_mode":{"name":"ipython","version":3},"pygments_lexer":"ipython3","nbconvert_exporter":"python","file_extension":".py"},"kaggle":{"accelerator":"none","dataSources":[],"dockerImageVersionId":30786,"isInternetEnabled":false,"language":"python","sourceType":"notebook","isGpuEnabled":false}},"nbformat_minor":4,"nbformat":4,"cells":[{"cell_type":"markdown","source":"Q1. Explain why we have to use the Exception class while creating a Custom Exception.","metadata":{}},{"cell_type":"markdown","source":"We use the Exception class as the base class when creating custom exceptions because:\n\nIntegration with Python’s Exception Handling: It ensures your custom exception is part of the standard exception hierarchy, making it catchable with try/except blocks.\n\nAccess to Built-in Features: By inheriting from Exception, your custom exception gains useful methods like __init__ and __str__ for handling error messages.\n\nStandardization: It maintains compatibility with Python’s built-in exception handling system, allowing for uniform error handling across your program..","metadata":{}},{"cell_type":"code","source":"","metadata":{"trusted":true},"outputs":[],"execution_count":null},{"cell_type":"markdown","source":"Q2. Write a python program to print Python Exception Hierarchy.","metadata":{}},{"cell_type":"code","source":"def print_exception_hierarchy():\n    for cls in Exception.__mro__:\n        print(cls.__name__)\n\nprint_exception_hierarchy()\n","metadata":{"trusted":true,"execution":{"iopub.status.busy":"2024-11-10T05:21:34.914767Z","iopub.execute_input":"2024-11-10T05:21:34.915194Z","iopub.status.idle":"2024-11-10T05:21:34.921197Z","shell.execute_reply.started":"2024-11-10T05:21:34.915154Z","shell.execute_reply":"2024-11-10T05:21:34.920162Z"}},"outputs":[{"name":"stdout","text":"Exception\nBaseException\nobject\n","output_type":"stream"}],"execution_count":2},{"cell_type":"code","source":"","metadata":{"trusted":true},"outputs":[],"execution_count":null},{"cell_type":"markdown","source":"Q3. What errors are defined in the ArithmeticError class? Explain any two with an example.","metadata":{}},{"cell_type":"markdown","source":"The ArithmeticError class has the following common subclasses:\n\nZeroDivisionError: Raised when dividing a number by zero.\n\nFloatingPointError: Raised when a floating-point operation fails.","metadata":{}},{"cell_type":"code","source":"try:\n    x = 10\n    y = 0\n    result = x / y  \nexcept ZeroDivisionError as e:\n    print(f\"Error: {e}\")\n","metadata":{"trusted":true,"execution":{"iopub.status.busy":"2024-11-10T05:23:40.001172Z","iopub.execute_input":"2024-11-10T05:23:40.001632Z","iopub.status.idle":"2024-11-10T05:23:40.008314Z","shell.execute_reply.started":"2024-11-10T05:23:40.001554Z","shell.execute_reply":"2024-11-10T05:23:40.007146Z"}},"outputs":[{"name":"stdout","text":"Error: division by zero\n","output_type":"stream"}],"execution_count":6},{"cell_type":"code","source":"import math\n\ntry:\n    result = math.sqrt(-1)\nexcept ValueError as e:\n    print(f\"ValueError: {e}\")\n","metadata":{"trusted":true,"execution":{"iopub.status.busy":"2024-11-10T05:23:33.984480Z","iopub.execute_input":"2024-11-10T05:23:33.984933Z","iopub.status.idle":"2024-11-10T05:23:33.991153Z","shell.execute_reply.started":"2024-11-10T05:23:33.984893Z","shell.execute_reply":"2024-11-10T05:23:33.989954Z"}},"outputs":[{"name":"stdout","text":"ValueError: math domain error\n","output_type":"stream"}],"execution_count":5},{"cell_type":"code","source":"","metadata":{"trusted":true},"outputs":[],"execution_count":null},{"cell_type":"markdown","source":"Q4. Why LookupError class is used? Explain with an example KeyError and IndexError.","metadata":{}},{"cell_type":"markdown","source":"The LookupError is the base class for exceptions related to invalid key or index lookups. It’s used to handle errors when trying to access elements using an invalid key in a dictionary or an index in a sequence like a list.\n\nKeyError: Raised when a dictionary key is not found.\n\nIndexError: Raised when an index is out of range in a sequence (like a list).","metadata":{}},{"cell_type":"code","source":"my_dict = {\"name\": \"Alice\"}\ntry:\n    value = my_dict[\"age\"]  # Key does not exist\nexcept KeyError as e:\n    print(f\"KeyError: {e}\")\n","metadata":{"trusted":true,"execution":{"iopub.status.busy":"2024-11-10T05:25:12.624507Z","iopub.execute_input":"2024-11-10T05:25:12.625560Z","iopub.status.idle":"2024-11-10T05:25:12.631589Z","shell.execute_reply.started":"2024-11-10T05:25:12.625506Z","shell.execute_reply":"2024-11-10T05:25:12.630557Z"}},"outputs":[{"name":"stdout","text":"KeyError: 'age'\n","output_type":"stream"}],"execution_count":7},{"cell_type":"code","source":"my_list = [10, 20, 30]\ntry:\n    value = my_list[5]  # Index out of range\nexcept IndexError as e:\n    print(f\"IndexError: {e}\")\n","metadata":{"trusted":true,"execution":{"iopub.status.busy":"2024-11-10T05:25:30.053836Z","iopub.execute_input":"2024-11-10T05:25:30.054695Z","iopub.status.idle":"2024-11-10T05:25:30.060858Z","shell.execute_reply.started":"2024-11-10T05:25:30.054634Z","shell.execute_reply":"2024-11-10T05:25:30.059629Z"}},"outputs":[{"name":"stdout","text":"IndexError: list index out of range\n","output_type":"stream"}],"execution_count":8},{"cell_type":"code","source":"","metadata":{"trusted":true},"outputs":[],"execution_count":null},{"cell_type":"markdown","source":"Q5. Explain ImportError. What is ModuleNotFoundError?","metadata":{}},{"cell_type":"markdown","source":"ImportError: Raised when there is an issue importing a module or specific attribute from a module.\n\nModuleNotFoundError: A subclass of ImportError, specifically raised when the module you are trying to import does not exist or cannot be found.","metadata":{}},{"cell_type":"code","source":"try:\n    from math import non_existent_function\nexcept ImportError as e:\n    print(f\"ImportError: {e}\")\n","metadata":{"trusted":true,"execution":{"iopub.status.busy":"2024-11-10T05:27:07.423755Z","iopub.execute_input":"2024-11-10T05:27:07.424960Z","iopub.status.idle":"2024-11-10T05:27:07.430725Z","shell.execute_reply.started":"2024-11-10T05:27:07.424911Z","shell.execute_reply":"2024-11-10T05:27:07.429551Z"}},"outputs":[{"name":"stdout","text":"ImportError: cannot import name 'non_existent_function' from 'math' (/opt/conda/lib/python3.10/lib-dynload/math.cpython-310-x86_64-linux-gnu.so)\n","output_type":"stream"}],"execution_count":11},{"cell_type":"code","source":"","metadata":{"trusted":true},"outputs":[],"execution_count":null},{"cell_type":"markdown","source":"Q6. List down some best practices for exception handling in python.","metadata":{}},{"cell_type":"markdown","source":"Catch Specific Exceptions: Always catch specific exceptions (e.g., KeyError, ValueError) instead of using a general except block.\n\nUse finally for Cleanup: Use the finally block for code that needs to run regardless of whether an exception occurs, such as closing files or releasing resources.\n\nLog Exceptions: Use Python’s logging module to log exceptions instead of just printing them, especially in production code.","metadata":{}},{"cell_type":"code","source":"","metadata":{"trusted":true},"outputs":[],"execution_count":null}]}